Workbook
Name Combine_scores: 'RFM Table'!$M:$M
Name F: 'RFM Table'!$K:$K
Name M: 'RFM Table'!$L:$L
Name OrderDate: SalesData!$B:$B
Name R_: 'RFM Table'!$J:$J
Name Slicer_Channel: #N/A
Name Slicer_City: #N/A
Name Slicer_ProductCategory: #N/A

Sheet Raw Data
A1: CustomerID | B1: OrderDate | C1: City | D1: ProductCategory | E1: Channel | F1: OrderValue
A2: 1194 | B2: 45406.375 | C2: Kakamega | D2: Fashion | E2: Retail Store | F2: 10942.56
A3: 1214 | B3: 45406.375 | C3: Nyeri | D3: Sports | E3: Retail Store | F3: 4652.84
A4: 1050 | B4: 45406.375 | C4: Meru | D4: Electronics | E4: Online | F4: 5521.47
A5: 1292 | B5: 45406.375 | C5: Thika | D5: Automotive | E5: Retail Store | F5: 13925.76
A6: 1245 | B6: 45406.375 | C6: Nakuru | D6: Fashion | E6: Mobile App | F6: 3502.98
A7: 1377 | B7: 45407.375 | C7: Thika | D7: Sports | E7: Online | F7: 9424.15
A8: 1381 | B8: 45408.375 | C8: Nakuru | D8: Fashion | E8: Online | F8: 2804.96
A9: 1156 | B9: 45408.375 | C9: Mombasa | D9: Automotive | E9: Online | F9: 676.55
A10: 1033 | B10: 45408.375 | C10: Nyeri | D10: Fashion | E10: Online | F10: 1221.2
A11: 1260 | B11: 45408.375 | C11: Nairobi | D11: Automotive | E11: Retail Store | F11: 4306.28
A12: 1199 | B12: 45409.375 | C12: Thika | D12: Beauty | E12: Mobile App | F12: 6020.75
A13: 1358 | B13: 45409.375 | C13: Mombasa | D13: Automotive | E13: Online | F13: 1958.78
... A3001: 1392 | B3001: 46135.375 | C3001: Meru | D3001: Beauty | E3001: Retail Store | F3001: 54.19

Sheet SalesData
A1: CustomerID | B1: OrderDate | C1: City | D1: ProductCategory | E1: Channel | F1: OrderValue
A2: 1194 | B2: 45406.375 | C2: Kakamega | D2: Fashion | E2: Retail Store | F2: 10942.56 | H2: Snapshot date | I2: =MAX(OrderDate) + 1 -> 46136.375
A3: 1214 | B3: 45406.375 | C3: Nyeri | D3: Sports | E3: Retail Store | F3: 4652.84
A4: 1050 | B4: 45406.375 | C4: Meru | D4: Electronics | E4: Online | F4: 5521.47
A5: 1292 | B5: 45406.375 | C5: Thika | D5: Automotive | E5: Retail Store | F5: 13925.76
A6: 1245 | B6: 45406.375 | C6: Nakuru | D6: Fashion | E6: Mobile App | F6: 3502.98
A7: 1377 | B7: 45407.375 | C7: Thika | D7: Sports | E7: Online | F7: 9424.15
A8: 1381 | B8: 45408.375 | C8: Nakuru | D8: Fashion | E8: Online | F8: 2804.96
A9: 1156 | B9: 45408.375 | C9: Mombasa | D9: Automotive | E9: Online | F9: 676.55
A10: 1033 | B10: 45408.375 | C10: Nyeri | D10: Fashion | E10: Online | F10: 1221.2
A11: 1260 | B11: 45408.375 | C11: Nairobi | D11: Automotive | E11: Retail Store | F11: 4306.28
A12: 1199 | B12: 45409.375 | C12: Thika | D12: Beauty | E12: Mobile App | F12: 6020.75
A13: 1358 | B13: 45409.375 | C13: Mombasa | D13: Automotive | E13: Online | F13: 1958.78
A14: 1358 | B14: 45409.375 | C14: Mombasa | D14: Groceries | E14: Mobile App | F14: 1557.18
... A3001: 1392 | B3001: 46135.375 | C3001: Meru | D3001: Beauty | E3001: Retail Store | F3001: 54.19

Sheet RFM Table
A1: CustomerID | B1: OrderDate | C1: City | D1: ProductCategory | E1: Channel | F1: OrderValue | G1: Recency | H1: Frequency | I1: Monetary | J1: R | K1: F | L1: M | M1: Combine_scores | N1: Segments
A2: 1194 | B2: 45406.375 | C2: Kakamega | D2: Fashion | E2: Retail Store | F2: 10942.56 | G2: {=SalesData!$I$2 - 'RFM Table'!B2} -> 730 | H2: {=COUNTIF(A:A,A2)} -> 7 | I2: {=SUMIF(A:A,A2,F:F)} -> 37031.05 | J2: {=5 - INT(5 * (RANK(G2,G:G, 1) - 1) / COUNT(G:G))} -> 1 | K2: {=INT(5 * (RANK(H2,H:H, 0) - 1) / COUNT(H:H)) + 1} -> 4 | L2: {=INT(5 * (RANK(I2,I:I, 0) - 1) / COUNT(I:I)) + 1} -> 2 | M2: =J2 & K2 & L2 -> 142 | N2: =IF(AND(J2>=4,K2<=2),"New Customers", IF(AND(J2<=2,K2>=3,L2>=3),"At Risk", IF(AND(J2<=2,K2<=2,L2>=3),"Can't Lose Them", IF(AND(J2<=2,K2<=2,L2<=2),"Lost", "Others")))) -> Others
A3: 1214 | B3: 45406.375 | C3: Nyeri | D3: Sports | E3: Retail Store | F3: 4652.84 | G3: {=SalesData!$I$2 - 'RFM Table'!B3} -> 730 | H3: {=COUNTIF(A:A,A3)} -> 12 | I3: {=SUMIF(A:A,A3,F:F)} -> 49382.65 | J3: {=5 - INT(5 * (RANK(G3,G:G, 1) - 1) / COUNT(G:G))} -> 1 | K3: {=INT(5 * (RANK(H3,H:H, 0) - 1) / COUNT(H:H)) + 1} -> 1 | L3: {=INT(5 * (RANK(I3,I:I, 0) - 1) / COUNT(I:I)) + 1} -> 1 | M3: =J3 & K3 & L3 -> 111 | N3: =IF(AND(J3>=4,K3<=2),"New Customers", IF(AND(J3<=2,K3>=3,L3>=3),"At Risk", IF(AND(J3<=2,K3<=2,L3>=3),"Can't Lose Them", IF(AND(J3<=2,K3<=2,L3<=2),"Lost", "Others")))) -> Lost
A4: 1050 | B4: 45406.375 | C4: Meru | D4: Electronics | E4: Online | F4: 5521.47 | G4: {=SalesData!$I$2 - 'RFM Table'!B4} -> 730 | H4: {=COUNTIF(A:A,A4)} -> 10 | I4: {=SUMIF(A:A,A4,F:F)} -> 32732.98 | J4: {=5 - INT(5 * (RANK(G4,G:G, 1) - 1) / COUNT(G:G))} -> 1 | K4: {=INT(5 * (RANK(H4,H:H, 0) - 1) / COUNT(H:H)) + 1} -> 2 | L4: {=INT(5 * (RANK(I4,I:I, 0) - 1) / COUNT(I:I)) + 1} -> 3 | M4: =J4 & K4 & L4 -> 123 | N4: =IF(AND(J4>=4,K4<=2),"New Customers", IF(AND(J4<=2,K4>=3,L4>=3),"At Risk", IF(AND(J4<=2,K4<=2,L4>=3),"Can't Lose Them", IF(AND(J4<=2,K4<=2,L4<=2),"Lost", "Others")))) -> Can't Lose Them
A5: 1292 | B5: 45406.375 | C5: Thika | D5: Automotive | E5: Retail Store | F5: 13925.76 | G5: {=SalesData!$I$2 - 'RFM Table'!B5} -> 730 | H5: {=COUNTIF(A:A,A5)} -> 15 | I5: {=SUMIF(A:A,A5,F:F)} -> 49638 | J5: {=5 - INT(5 * (RANK(G5,G:G, 1) - 1) / COUNT(G:G))} -> 1 | K5: {=INT(5 * (RANK(H5,H:H, 0) - 1) / COUNT(H:H)) + 1} -> 1 | L5: {=INT(5 * (RANK(I5,I:I, 0) - 1) / COUNT(I:I)) + 1} -> 1 | M5: =J5 & K5 & L5 -> 111 | N5: =IF(AND(J5>=4,K5<=2),"New Customers", IF(AND(J5<=2,K5>=3,L5>=3),"At Risk", IF(AND(J5<=2,K5<=2,L5>=3),"Can't Lose Them", IF(AND(J5<=2,K5<=2,L5<=2),"Lost", "Others")))) -> Lost
A6: 1245 | B6: 45406.375 | C6: Nakuru | D6: Fashion | E6: Mobile App | F6: 3502.98 | G6: {=SalesData!$I$2 - 'RFM Table'!B6} -> 730 | H6: {=COUNTIF(A:A,A6)} -> 6 | I6: {=SUMIF(A:A,A6,F:F)} -> 17570.61 | J6: {=5 - INT(5 * (RANK(G6,G:G, 1) - 1) / COUNT(G:G))} -> 1 | K6: {=INT(5 * (RANK(H6,H:H, 0) - 1) / COUNT(H:H)) + 1} -> 4 | L6: {=INT(5 * (RANK(I6,I:I, 0) - 1) / COUNT(I:I)) + 1} -> 5 | M6: =J6 & K6 & L6 -> 145 | N6: =IF(AND(J6>=4,K6<=2),"New Customers", IF(AND(J6<=2,K6>=3,L6>=3),"At Risk", IF(AND(J6<=2,K6<=2,L6>=3),"Can't Lose Them", IF(AND(J6<=2,K6<=2,L6<=2),"Lost", "Others")))) -> At Risk
A7: 1377 | B7: 45407.375 | C7: Thika | D7: Sports | E7: Online | F7: 9424.15 | G7: {=SalesData!$I$2 - 'RFM Table'!B7} -> 729 | H7: {=COUNTIF(A:A,A7)} -> 6 | I7: {=SUMIF(A:A,A7,F:F)} -> 39626.31 | J7: {=5 - INT(5 * (RANK(G7,G:G, 1) - 1) / COUNT(G:G))} -> 1 | K7: {=INT(5 * (RANK(H7,H:H, 0) - 1) / COUNT(H:H)) + 1} -> 4 | L7: {=INT(5 * (RANK(I7,I:I, 0) - 1) / COUNT(I:I)) + 1} -> 2 | M7: =J7 & K7 & L7 -> 142 | N7: =IF(AND(J7>=4,K7<=2),"New Customers", IF(AND(J7<=2,K7>=3,L7>=3),"At Risk", IF(AND(J7<=2,K7<=2,L7>=3),"Can't Lose Them", IF(AND(J7<=2,K7<=2,L7<=2),"Lost", "Others")))) -> Others
A8: 1381 | B8: 45408.375 | C8: Nakuru | D8: Fashion | E8: Online | F8: 2804.96 | G8: {=SalesData!$I$2 - 'RFM Table'!B8} -> 728 | H8: {=COUNTIF(A:A,A8)} -> 7 | I8: {=SUMIF(A:A,A8,F:F)} -> 32953.6 | J8: {=5 - INT(5 * (RANK(G8,G:G, 1) - 1) / COUNT(G:G))} -> 1 | K8: {=INT(5 * (RANK(H8,H:H, 0) - 1) / COUNT(H:H)) + 1} -> 4 | L8: {=INT(5 * (RANK(I8,I:I, 0) - 1) / COUNT(I:I)) + 1} -> 3 | M8: =J8 & K8 & L8 -> 143 | N8: =IF(AND(J8>=4,K8<=2),"New Customers", IF(AND(J8<=2,K8>=3,L8>=3),"At Risk", IF(AND(J8<=2,K8<=2,L8>=3),"Can't Lose Them", IF(AND(J8<=2,K8<=2,L8<=2),"Lost", "Others")))) -> At Risk
A9: 1156 | B9: 45408.375 | C9: Mombasa | D9: Automotive | E9: Online | F9: 676.55 | G9: {=SalesData!$I$2 - 'RFM Table'!B9} -> 728 | H9: {=COUNTIF(A:A,A9)} -> 8 | I9: {=SUMIF(A:A,A9,F:F)} -> 43799.99 | J9: {=5 - INT(5 * (RANK(G9,G:G, 1) - 1) / COUNT(G:G))} -> 1 | K9: {=INT(5 * (RANK(H9,H:H, 0) - 1) / COUNT(H:H)) + 1} -> 3 | L9: {=INT(5 * (RANK(I9,I:I, 0) - 1) / COUNT(I:I)) + 1} -> 2 | M9: =J9 & K9 & L9 -> 132 | N9: =IF(AND(J9>=4,K9<=2),"New Customers", IF(AND(J9<=2,K9>=3,L9>=3),"At Risk", IF(AND(J9<=2,K9<=2,L9>=3),"Can't Lose Them", IF(AND(J9<=2,K9<=2,L9<=2),"Lost", "Others")))) -> Others
A10: 1033 | B10: 45408.375 | C10: Nyeri | D10: Fashion | E10: Online | F10: 1221.2 | G10: {=SalesData!$I$2 - 'RFM Table'!B10} -> 728 | H10: {=COUNTIF(A:A,A10)} -> 7 | I10: {=SUMIF(A:A,A10,F:F)} -> 18694.46 | J10: {=5 - INT(5 * (RANK(G10,G:G, 1) - 1) / COUNT(G:G))} -> 1 | K10: {=INT(5 * (RANK(H10,H:H, 0) - 1) / COUNT(H:H)) + 1} -> 4 | L10: {=INT(5 * (RANK(I10,I:I, 0) - 1) / COUNT(I:I)) + 1} -> 5 | M10: =J10 & K10 & L10 -> 145 | N10: =IF(AND(J10>=4,K10<=2),"New Customers", IF(AND(J10<=2,K10>=3,L10>=3),"At Risk", IF(AND(J10<=2,K10<=2,L10>=3),"Can't Lose Them", IF(AND(J10<=2,K10<=2,L10<=2),"Lost", "Others")))) -> At Risk
A11: 1260 | B11: 45408.375 | C11: Nairobi | D11: Automotive | E11: Retail Store | F11: 4306.28 | G11: {=SalesData!$I$2 - 'RFM Table'!B11} -> 728 | H11: {=COUNTIF(A:A,A11)} -> 10 | I11: {=SUMIF(A:A,A11,F:F)} -> 67378.48 | J11: {=5 - INT(5 * (RANK(G11,G:G, 1) - 1) / COUNT(G:G))} -> 1 | K11: {=INT(5 * (RANK(H11,H:H, 0) - 1) / COUNT(H:H)) + 1} -> 2 | L11: {=INT(5 * (RANK(I11,I:I, 0) - 1) / COUNT(I:I)) + 1} -> 1 | M11: =J11 & K11 & L11 -> 121 | N11: =IF(AND(J11>=4,K11<=2),"New Customers", IF(AND(J11<=2,K11>=3,L11>=3),"At Risk", IF(AND(J11<=2,K11<=2,L11>=3),"Can't Lose Them", IF(AND(J11<=2,K11<=2,L11<=2),"Lost", "Others")))) -> Lost
A12: 1199 | B12: 45409.375 | C12: Thika | D12: Beauty | E12: Mobile App | F12: 6020.75 | G12: {=SalesData!$I$2 - 'RFM Table'!B12} -> 727 | H12: {=COUNTIF(A:A,A12)} -> 5 | I12: {=SUMIF(A:A,A12,F:F)} -> 17477.02 | J12: {=5 - INT(5 * (RANK(G12,G:G, 1) - 1) / COUNT(G:G))} -> 1 | K12: {=INT(5 * (RANK(H12,H:H, 0) - 1) / COUNT(H:H)) + 1} -> 5 | L12: {=INT(5 * (RANK(I12,I:I, 0) - 1) / COUNT(I:I)) + 1} -> 5 | M12: =J12 & K12 & L12 -> 155 | N12: =IF(AND(J12>=4,K12<=2),"New Customers", IF(AND(J12<=2,K12>=3,L12>=3),"At Risk", IF(AND(J12<=2,K12<=2,L12>=3),"Can't Lose Them", IF(AND(J12<=2,K12<=2,L12<=2),"Lost", "Others")))) -> At Risk
A13: 1358 | B13: 45409.375 | C13: Mombasa | D13: Automotive | E13: Online | F13: 1958.78 | G13: {=SalesData!$I$2 - 'RFM Table'!B13} -> 727 | H13: {=COUNTIF(A:A,A13)} -> 9 | I13: {=SUMIF(A:A,A13,F:F)} -> 29151.88 | J13: {=5 - INT(5 * (RANK(G13,G:G, 1) - 1) / COUNT(G:G))} -> 1 | K13: {=INT(5 * (RANK(H13,H:H, 0) - 1) / COUNT(H:H)) + 1} -> 2 | L13: {=INT(5 * (RANK(I13,I:I, 0) - 1) / COUNT(I:I)) + 1} -> 4 | M13: =J13 & K13 & L13 -> 124 | N13: =IF(AND(J13>=4,K13<=2),"New Customers", IF(AND(J13<=2,K13>=3,L13>=3),"At Risk", IF(AND(J13<=2,K13<=2,L13>=3),"Can't Lose Them", IF(AND(J13<=2,K13<=2,L13<=2),"Lost", "Others")))) -> Can't Lose Them
... A3001: 1392 | B3001: 46135.375 | C3001: Meru | D3001: Beauty | E3001: Retail Store | F3001: 54.19 | G3001: {=SalesData!$I$2 - 'RFM Table'!B3001} -> 1 | H3001: {=COUNTIF(A:A,A3001)} -> 10 | I3001: {=SUMIF(A:A,A3001,F:F)} -> 27910.07 | J3001: {=5 - INT(5 * (RANK(G3001,G:G, 1) - 1) / COUNT(G:G))} -> 5 | K3001: {=INT(5 * (RANK(H3001,H:H, 0) - 1) / COUNT(H:H)) + 1} -> 2 | L3001: {=INT(5 * (RANK(I3001,I:I, 0) - 1) / COUNT(I:I)) + 1} -> 4 | M3001: =J3001 & K3001 & L3001 -> 524 | N3001: =IF(AND(J3001>=4,K3001<=2),"New Customers", IF(AND(J3001<=2,K3001>=3,L3001>=3),"At Risk", IF(AND(J3001<=2,K3001<=2,L3001>=3),"Can't Lose Them", IF(AND(J3001<=2,K3001<=2,L3001<=2),"Lost", "Others")))) -> New Customers

Sheet Pivot Analysis
A1: Row Labels | B1: Count of CustomerID | C1: Total Sales
A2: Can't Lose Them | B2: 179 | C2: 604550.87 | D2: =A2 -> Can't Lose Them | E2: =B2 -> 179 | F2: =C2 -> 604550.87 | H2: Total Sales | I2: =F7 -> 11923425
A3: Lost | B3: 420 | C3: 1793348.9 | D3: =A3 -> Lost | E3: =B3 -> 420 | F3: =C3 -> 1793348.9 | H3: Total Orders | I3: =GETPIVOTDATA("Count of CustomerID",$A$1) -> 3000
A4: At Risk | B4: 539 | C4: 2014410.7 | D4: =A4 -> At Risk | E4: =B4 -> 539 | F4: =C4 -> 2014410.7 | H4: Avg Order Value | I4: =I2/I3 -> 3974.475
A5: New Customers | B5: 615 | C5: 2512608.5 | D5: =A5 -> New Customers | E5: =B5 -> 615 | F5: =C5 -> 2512608.5
A6: Others | B6: 1247 | C6: 4998506 | D6: =A6 -> Others | E6: =B6 -> 1247 | F6: =C6 -> 4998506
A7: Grand Total | B7: 3000 | C7: 11923425 | D7: =A7 -> Grand Total | E7: =B7 -> 3000 | F7: =C7 -> 11923425
A11: Tota Orders | B11: =GETPIVOTDATA("Count of CustomerID",$A$1) -> 3000
A12: Avg Order Value | B12: =F7/B11 -> 3974.475
A20: Row Labels | B20: Sum of OrderValue
A21: 1000 | B21: 62566.77
A22: 1013 | B22: 60099.84
A23: 1038 | B23: 76962.72
A24: 1110 | B24: 72511.88
A25: 1144 | B25: 62038.55
A26: 1148 | B26: 83986.3
A27: 1172 | B27: 64175.24
A28: 1260 | B28: 67378.48
A29: 1287 | B29: 64716.25
A30: 1385 | B30: 73437.08
A31: Grand Total | B31: 687873.11
A37: Row Labels | B37: Count of CustomerID
A38: Eldoret | B38: 294
A39: Kakamega | B39: 307
A40: Kisumu | B40: 296
A41: Machakos | B41: 304
A42: Meru | B42: 267
A43: Mombasa | B43: 303
A44: Nairobi | B44: 315
A45: Nakuru | B45: 315
A46: Nyeri | B46: 305
A47: Thika | B47: 294
A48: Grand Total | B48: 3000
A53: Row Labels | B53: Total Sales
A54: Mobile App | B54: 3891306.1
A55: Online | B55: 3894900
A56: Retail Store | B56: 4137218.9
A57: Grand Total | B57: 11923425
A66: Row Labels | B66: Count of CustomerID | C66: Sum of OrderValue
A67: At Risk | B67: 539 | C67: 2014410.7
...

Sheet Dashboard
A1: Customer Segmentation Dashboard (RFM) Analysis

Sheet Insights
A1: Insights
A3: Others Segment contribute the most to sales
A4: At Risk segment shows declining engagement within last 180 days
A5: Retails Channel contribute the most to the Sales
